Workbook
Name nem_modosithato2: Irányelvek!$L:$L,Irányelvek!$K:$K,Irányelvek!$J$1,Irányelvek!$I:$I,Irányelvek!$J:$J,Irányelvek!$H:$H,Irányelvek!$C:$C,Irányelvek!$B:$B,Irányelvek!$A:$A

Sheet Fedőlap
B1: Web-fejlesztés kurzus beadandó feladata | J1: Verzió: v2025262_v2
B2: Neved:
B3: Neptun kódod:
B4: E-mail címed:
B5: A honlapot tesztelés céljából érdemes publikálni egy webszerveren még a beadás előtt. Azonban értékelésre a Canvas-ba feltöltött tömörített csomag kerül, amelyet saját webszerveren publikálunk.
B6: Az irányelvek megtekintése és az adatlap kitöltése
B7: =CONCATENATE("Az irányelvek között vannak kiemelt (sárga háttérszínnel és félkövér kiemeléssel jelölt) elvek , amelyek betartására kiemelten figyelni kell! Az elégséges szinthez legalább ",D12," pontot el kell érni. A hallgatói és tutori értékelés tekintetében, maximum 15 darab irányelvben lehet eltérés, ennél több esetén már nem tudjuk elfogadni a feladatot.") -> Az irányelvek között vannak kiemelt (sárga háttérszínnel és félkövér kiemeléssel jelölt) elvek , amelyek betartására kiemelten figyelni kell! Az elégséges szinthez legalább 50 pontot el kell érni. A hallgatói és tutori értékelés tekintetében, maximum 15 darab irányelvben lehet eltérés, ennél több esetén már nem tudjuk elfogadni a feladatot.
B9: Irányelvek
B10: Az irányelvek száma: | D10: =COUNTA(Irányelvek!B:B)-1 -> 46 | F10: A táblázatot Excelben kérjük kitölteni (laborokban fel van telepítve), mivel az összesítő alkalmazás csak az eredeti XLSX állományokon működik. Más formátumú táblázatokat nem fogadunk el.
B11: Az irányelvek teljesítésére kapható maximális pontszám: | D11: =SUM(Irányelvek!I:I) -> 100
B12: A honlap elfogadásához szükséges minimális pontszám: | D12: 50
B13: Hallgatói önértékelés eredménye
B14: Az önértékelésed alapján minden kiemelt irányelvet teljesítettél: | D14: =IF(COUNTIFS(Irányelvek!D2:D47,"=1",Irányelvek!H2:H47,"=igaz")=19,TRUE,FALSE) -> FALSE
B15: Az önellenőrzés során elért összpontszámod: | D15: =SUM(Irányelvek!J2:J47) -> 100 | F15: =CONCATENATE("Ha a feladatot önállóan értékelnénk, akkor az önértékelésed alapján ",VLOOKUP(D15,Ponthatárok!$C$3:$D$7,2,TRUE), " érdemjegyet kapnál rá.") -> Ha a feladatot önállóan értékelnénk, akkor az önértékelésed alapján jeles érdemjegyet kapnál rá.
B16: Tutori értékelés eredménye
B17: A tutori értékelés alapján minden kiemelt irányelvet teljesítettél: | D17: =IF(D26=TRUE,IF(COUNTIFS(Irányelvek!F2:F47,"=1",Irányelvek!H2:H47,"=igaz")=19,TRUE,FALSE),"Még nincs adat.") -> Még nincs adat. | F17: Csak akkor van jelentősége, ha már a tutor is elvégezte az értékelést.
B18: A tutori értékelés (ellenőrzés) során elért összpontszámod: | D18: =IF(D26=TRUE,SUM(Irányelvek!K2:K47),"Még nincs adat.") -> Még nincs adat.
B19: Az összpontszám a tutor által kiosztott további pontszámok alapján | D19: =IF(D26=TRUE,D18+D27,"Még nincs adat.") -> Még nincs adat.
B20: Önértékelés szakmaisága
B21: Az önértékelés helyességére járó maximális pontszám | D21: 20 | F21: Csak akkor van jelentősége, ha már a tutor is elvégezte az értékelést.
B22: Az értékelés elfogadásához szükséges minimális pontszám | D22: 10
B23: A hallgatói és tutori értékelés közti különbség az irányelveket (nem pedig pontszámot) tekintve: | D23: =IF(D26=TRUE,SUM(Irányelvek!L2:L47),"Még nincs adat.") -> Még nincs adat.
B24: A hallgató pontszáma az önértékelés szakmaiságát tekintve: | D24: =IF(D26,IF(ROUNDUP(20 - 0.71*D23,0)>0,ROUNDUP(20 - 0.71*D23,0),0),"Még nincs adat.") -> Még nincs adat.
B26: A tutor elvégezte az értékelést az irányelvek alapján: | D26: FALSE
B27: A tutor által kiosztott további pontszám az alapján, hogy az előadáson ismertett egyéb elvek milyen mértékben teljesültek (lehet pozitív és negatív is)
B28: A tutor szöveges értékelése (opcionális)

Sheet Irányelvek
B1: Kategória | C1: Teljesítési feltétel | D1: Az irányelv teljesül? [1 ha igen, 0 ha nem] (hallgatói önértékelés) | E1: Hallgató megjegyzése (üres cellák esetén opcionális) | F1: Az irányelv teljesül? [1/0] (tutori értékelés) | G1: Tutor megjegyzése | H1: Kiemelt irányelv? | I1: Pontszám, ha teljesül | J1: Kapott pontszám (önértékelés) | K1: Kapott pontszám (tutor értékelése) | L1: Eltérés
A2: 1 | B2: Kurzus követelmény | C2: A weblap legalább három, statikus HTML oldalból áll, a kezdőlap index.html néven lett elmentve. Minden HTML oldal, ami a csomagban van, be is van linkelve az oldalakra, nincs felesleges HTML állomány. Az oldalak relatív módon vannak linkelve, nincs gyökérmappára való hivatkozás. | D2: 1 | H2: TRUE | I2: 3 | J2: =IF(D2=1,I2,IF(H2=TRUE,-5,"")) -> 3 | K2: =IF(F2=1,I2,IF(H2=TRUE,-5,"")) -> -5 | L2: =IF(J2=K2,0,1) -> 1
A3: =A2+1 -> 2 | B3: Kurzus követelmény | C3: Van (legalább egy) olyan oldal, amely háttérképet tartalmaz (Nem muszáj, hogy a háttérkép a lap háttere legyen, lehet egy tetszőleges komponensé is.) | D3: 1 | E3: resources.html legalján | H3: TRUE | I3: 2 | J3: =IF(D3=1,I3,IF(H3=TRUE,-5,"")) -> 2 | K3: =IF(F3=1,I3,IF(H3=TRUE,-5,"")) -> -5 | L3: =IF(J3=K3,0,1) -> 1
A4: =A3+1 -> 3 | B4: Kurzus követelmény | C4: Az oldalak összesen legalább öt képet tartalmaznak. Ezek közül legalább két kép előképként (thumbnail) funkcionál, vagyis a fizikailag kisebb méretű kép a hozzá tartozó nagyobb képváltozatra linkel. | D4: 1 | E4: projects.html-ben van 5 kép, és belőle 4 thumbnailként funkcionál | H4: TRUE | I4: 3 | J4: =IF(D4=1,I4,IF(H4=TRUE,-5,"")) -> 3 | K4: =IF(F4=1,I4,IF(H4=TRUE,-5,"")) -> -5 | L4: =IF(J4=K4,0,1) -> 1
A5: =A4+1 -> 4 | B5: Kurzus követelmény | C5: Van olyan oldal, amelyen van olyan adattáblázat, amely legalább 2x3-as és vannak fejléc-cellái (<th>). A táblázat felirata (<caption>), lenyitható tartalomként lett elkészítve a <details> tag-be ágyazott <summary> tag segítségével. Az oldal struktúráját nem szabad táblázat segítségével megvalósítani! | D5: 1 | E5: a cheat-sheets.html oldal első táblázata | H5: TRUE | I5: 3 | J5: =IF(D5=1,I5,IF(H5=TRUE,-5,"")) -> 3 | K5: =IF(F5=1,I5,IF(H5=TRUE,-5,"")) -> -5 | L5: =IF(J5=K5,0,1) -> 1
A6: =A5+1 -> 5 | B6: Kurzus követelmény | C6: Van olyan oldal, amelyben egy olyan űrlap található, amely tartalmaz legalább egy szövegmezőt (text), egy szövegterületet (textarea),legalább 2 választókapcsolót (radio), legalább 1 jelölőnégyzetet (checkbox), valamint egy elküldés (submit) gombot. | D6: 1 | E6: resources.html legalján | H6: TRUE | I6: 3 | J6: =IF(D6=1,I6,IF(H6=TRUE,-5,"")) -> 3 | K6: =IF(F6=1,I6,IF(H6=TRUE,-5,"")) -> -5 | L6: =IF(J6=K6,0,1) -> 1
A7: =A6+1 -> 6 | B7: Kurzus követelmény | C7: Van olyan oldal, amelyben egy felhasználói élményt javító JavaScript kód van beillesztve (pl. választás alternatív stíluslapból, betűméret váltás, képgaléria, ...) A Bootstrap keretrendszer komponensei is elfogadhatóak ennél a pontnál (pl. Carousel). | D7: 1 | E7: van sötét/világos mód kiválasztó, search modal keresés (ami gomra kattintáskor és gyorsgombbal is működik), back to top gomb megjelenése ha legörgetünk túlságosan, és egy pár kissebb extra dolog. | H7: TRUE | I7: 3 | J7: =IF(D7=1,I7,IF(H7=TRUE,-5,"")) -> 3 | K7: =IF(F7=1,I7,IF(H7=TRUE,-5,"")) -> -5 | L7: =IF(J7=K7,0,1) -> 1
A8: =A7+1 -> 7 | B8: Kurzus követelmény | C8: Az oldalak mindegyike tartalommal fel van töltve, a szerkezeti linkeken kívül legalább 3 külső hivatkozást is tartalmaznak (összesen). A Lorem ipsum,stb. töltelékszövegekkel feltöltött oldalak nem elfogadhatóak! A szerkezeti linkek az aktuális oldalhoz képest relatívan vannak megadva. | D8: 1 | E8: elég sok külső hivatkozás van, és minden fel van töltve tartalommal | H8: TRUE | I8: 2 | J8: =IF(D8=1,I8,IF(H8=TRUE,-5,"")) -> 2 | K8: =IF(F8=1,I8,IF(H8=TRUE,-5,"")) -> -5 | L8: =IF(J8=K8,0,1) -> 1
A9: =A8+1 -> 8 | B9: Kurzus követelmény | C9: A HTML5-s oldal(ak)on az alábbi tagek mindegyikének használatára van példa: <header><nav><section><article><aside><footer><figure><video>. A tageknek nem kell minden oldalon előfordulniuk, de amikor szemantikailag indokolt a használatuk, akkor a megfelelő taget KELL használni! | D9: 1 | H9: TRUE | I9: 4 | J9: =IF(D9=1,I9,IF(H9=TRUE,-5,"")) -> 4 | K9: =IF(F9=1,I9,IF(H9=TRUE,-5,"")) -> -5 | L9: =IF(J9=K9,0,1) -> 1
A10: =A9+1 -> 9 | B10: Oldaltervezés | C10: Az elkészült weblap reszponzív. Ezen felül igaz legalább 1 oldal esetén, hogy a kijelzőmérettől függően legalább háromféle elrendezés van megvalósítva (okostelefon, tablet, nagyobb kijelző), amelyek közül a (leg)kisebb kijelzőméretre tervezett elrendezés egyetlen oszlopból áll, a (leg)nagyobbra tervezett pedig legalább két oszlopból. A tartalmi elemek (beleértve a képeket és a videókat) minden oldalon relatívan vannak méretezve. | D10: 1 | E10: 3 fajlta elrendezés van, amit a css/responsivity.css -ben van leírva. A fejléc 1 oszlop, ha telefon méretű, 2 tablet méret esetén, és 3 oszlop nagy kijelző esetén. Minden más relatívan van méretezve, és minden látható és helyesen val elhelyezve mindhárom méretben. | H10: TRUE | I10: 5 | J10: =IF(D10=1,I10,IF(H10=TRUE,-5,"")) -> 5 | K10: =IF(F10=1,I10,IF(H10=TRUE,-5,"")) -> -5 | L10: =IF(J10=K10,0,1) -> 1
A11: =A10+1 -> 10 | B11: Oldaltervezés | C11: A tartalom és a megjelenés megfelelően el van különítve egymástól külső stíluslap(ok) használatával. Inline, illetve internal stílusmegadás használata nem engedélyezett. | D11: 1 | E11: css/ mappában | H11: TRUE | I11: 3 | J11: =IF(D11=1,I11,IF(H11=TRUE,-5,"")) -> 3 | K11: =IF(F11=1,I11,IF(H11=TRUE,-5,"")) -> -5 | L11: =IF(J11=K11,0,1) -> 1
A12: =A11+1 -> 11 | B12: Oldaltervezés | C12: Az oldalcímek minden oldalon egy, az adott oldal tartalmára utaló kulcsszóval kezdődnek vagy végződnek, és a teljes webhelyen egységesen használt webhely nevét tartalmazzák. (pl. Magamról – Gipsz Jakab honlapja; Gipsz Jakab honlapja – Magamról) | D12: 1 | I12: 1 | J12: =IF(D12=1,I12,IF(H12=TRUE,-5,"")) -> 1 | K12: =IF(F12=1,I12,IF(H12=TRUE,-5,"")) | L12: =IF(J12=K12,0,1) -> 1
A13: =A12+1 -> 12 | B13: Oldaltervezés | C13: A szöveg a megadott alapméretben jól olvasható | D13: 1 | I13: 1 | J13: =IF(D13=1,I13,IF(H13=TRUE,-5,"")) -> 1 | K13: =IF(F13=1,I13,IF(H13=TRUE,-5,"")) | L13: =IF(J13=K13,0,1) -> 1
A14: =A13+1 -> 13 | B14: Oldaltervezés | C14: A betűtípus megadásoknál konkrét betűtípusok és általános betűcsaládok is meg vannak adva, a kisebb méretű szövegeknél talpnélküli (sans-serif) betűtípus van beállítva | D14: 1 | I14: 1 | J14: =IF(D14=1,I14,IF(H14=TRUE,-5,"")) -> 1 | K14: =IF(F14=1,I14,IF(H14=TRUE,-5,"")) | L14: =IF(J14=K14,0,1) -> 1
A15: =A14+1 -> 14 | B15: Oldaltervezés | C15: A betűméretek oly módon vannak megadva, hogy könnyen átméretezhető legyen a szöveg (%,em, vagy rem megadással) | D15: 1 | I15: 1 | J15: =IF(D15=1,I15,IF(H15=TRUE,-5,"")) -> 1 | K15: =IF(F15=1,I15,IF(H15=TRUE,-5,"")) | L15: =IF(J15=K15,0,1) -> 1
A16: =A15+1 -> 15 | B16: Oldaltervezés | C16: A menüsor felül, vagy bal oldalon helyezkedik el, megfelelően elkülönül a tartalomtól (pl. színezett hátterű) | D16: 1 | I16: 1 | J16: =IF(D16=1,I16,IF(H16=TRUE,-5,"")) -> 1 | K16: =IF(F16=1,I16,IF(H16=TRUE,-5,"")) | L16: =IF(J16=K16,0,1) -> 1
A17: =A16+1 -> 16 | B17: Oldaltervezés | C17: Kinézetükben különböznek a még nem látogatott és látogatott linkek. A már látogatott link kontrasztaránya kisebb a nem látogatotthoz képest. A menü esetén ez nem feltétel. | D17: 1 | E17: css/basic-settings.css -ben van benne | I17: 1 | J17: =IF(D17=1,I17,IF(H17=TRUE,-5,"")) -> 1 | K17: =IF(F17=1,I17,IF(H17=TRUE,-5,"")) | L17: =IF(J17=K17,0,1) -> 1
A18: =A17+1 -> 17 | B18: Oldaltervezés | C18: Nincs olyan szöveg aláhúzva, ami nem tölt be link szerepet | D18: 1 | I18: 1 | J18: =IF(D18=1,I18,IF(H18=TRUE,-5,"")) -> 1 | K18: =IF(F18=1,I18,IF(H18=TRUE,-5,"")) | L18: =IF(J18=K18,0,1) -> 1
A19: =A18+1 -> 18 | B19: Oldaltervezés | C19: A linkek alá vannak húzva a szövegben, kivétel lehet a navigációs menü és linklista. Nem elegendő, hogy az aláhúzás csak akkor jelenik meg, amikor a felhasználó a link fölé vitte az egeret. Az aláhúzásnak mindig láthatónak kell lennie. | D19: 1 | I19: 1 | J19: =IF(D19=1,I19,IF(H19=TRUE,-5,"")) -> 1 | K19: =IF(F19=1,I19,IF(H19=TRUE,-5,"")) | L19: =IF(J19=K19,0,1) -> 1
A20: =A19+1 -> 19 | B20: Oldaltervezés | C20: Az oldalak jól nyomtathatók, a nyomtatási képen minden fontos információ látszik. A képernyő és a nyomtató számára külön stíluslapot kell készíteni. A nyomtatási nézetben el kell tüntetni a minden oldalon ismétlődő elemeket, így például a menüt, a fejlécet, az oldalsávot stb. A videók legyenek elrejtve, a képek pedig legyenek kicsinyítve. A szöveg papír- és festéktakarékosan töltse ki az oldalakat. | D20: 1 | E20: css/print.css -ben van leírva. | I20: 3 | J20: =IF(D20=1,I20,IF(H20=TRUE,-5,"")) -> 3 | K20: =IF(F20=1,I20,IF(H20=TRUE,-5,"")) | L20: =IF(J20=K20,0,1) -> 1
A21: =A20+1 -> 20 | B21: Oldaltervezés | C21: Az űrlapelemeknél van megfelelően hozzárendelt címke (label for="") és egyértelműen utal arra, hogy milyen információt kell az űrlapelemben szerepeltetni | D21: 1 | I21: 3 | J21: =IF(D21=1,I21,IF(H21=TRUE,-5,"")) -> 3 | K21: =IF(F21=1,I21,IF(H21=TRUE,-5,"")) | L21: =IF(J21=K21,0,1) -> 1
A22: =A21+1 -> 21 | B22: Oldaltervezés | C22: Az űrlap szövegmezői a várt adatnak megfelelő hosszúságúak A szövegmezők méretét és a begépelhető szöveg maximális hosszát is be kell állítani. A méret beállításhoz használható stíluslap is. | D22: 1 | I22: 1 | J22: =IF(D22=1,I22,IF(H22=TRUE,-5,"")) -> 1 | K22: =IF(F22=1,I22,IF(H22=TRUE,-5,"")) | L22: =IF(J22=K22,0,1) -> 1
A23: =A22+1 -> 22 | B23: Oldaltervezés | C23: Az űrlap címkéi közel vannak az űrlapmezőkhöz, így nem gyengül az asszociáció | D23: 1 | I23: 1 | J23: =IF(D23=1,I23,IF(H23=TRUE,-5,"")) -> 1 | K23: =IF(F23=1,I23,IF(H23=TRUE,-5,"")) | L23: =IF(J23=K23,0,1) -> 1
A24: =A23+1 -> 23 | B24: Oldaltervezés | C24: Az űrlap tartalma elküldhető (e-mailben post metódussal, vagy más módon feldolgozásra kerül) | D24: 1 | I24: 1 | J24: =IF(D24=1,I24,IF(H24=TRUE,-5,"")) -> 1 | K24: =IF(F24=1,I24,IF(H24=TRUE,-5,"")) | L24: =IF(J24=K24,0,1) -> 1
A25: =A24+1 -> 24 | B25: Oldaltervezés | C25: Az űrlapok választókapcsolói (radio) minden lehetséges választ lefednek | D25: 1 | I25: 1 | J25: =IF(D25=1,I25,IF(H25=TRUE,-5,"")) -> 1 | K25: =IF(F25=1,I25,IF(H25=TRUE,-5,"")) | L25: =IF(J25=K25,0,1) -> 1
A26: =A25+1 -> 25 | B26: Oldaltervezés | C26: Az űrlapnál a nyomógomb funkcióját egyértelműen jelzi a felirata | D26: 1 | I26: 1 | J26: =IF(D26=1,I26,IF(H26=TRUE,-5,"")) -> 1 | K26: =IF(F26=1,I26,IF(H26=TRUE,-5,"")) | L26: =IF(J26=K26,0,1) -> 1
A27: =A26+1 -> 26 | B27: Tartalomtervezés | C27: A letapogathatóság elve alapján a kulcsszavak ki vannak emelve (félkövér, dőlt), ahol az értelmes, felsoroláslista lett használva | D27: 1 | I27: 2 | J27: =IF(D27=1,I27,IF(H27=TRUE,-5,"")) -> 2 | K27: =IF(F27=1,I27,IF(H27=TRUE,-5,"")) | L27: =IF(J27=K27,0,1) -> 1
A28: =A27+1 -> 27 | B28: Tartalomtervezés | C28: Értelmesen megfogalmazott címsorok (<h1>…<h6>) tagolják a szöveget minden egyes oldalon. A HTML5-ös oldalakon a címsorszinteket egymásba ágyazott oldalszerkezeti elemekben szerepeltetett <h1> címsorral is be lehet állítani. Ha nem indokolt az alcímsorok használata, akkor elég egy <h1> taget elhelyezni. | D28: 1 | I28: 2 | J28: =IF(D28=1,I28,IF(H28=TRUE,-5,"")) -> 2 | K28: =IF(F28=1,I28,IF(H28=TRUE,-5,"")) | L28: =IF(J28=K28,0,1) -> 1
A29: =A28+1 -> 28 | B29: Tartalomtervezés | C29: Nincs olyan mintás háttér alkalmazva, amely megnehezíti a rajta lévő szöveg elolvasását | D29: 1 | I29: 1 | J29: =IF(D29=1,I29,IF(H29=TRUE,-5,"")) -> 1 | K29: =IF(F29=1,I29,IF(H29=TRUE,-5,"")) | L29: =IF(J29=K29,0,1) -> 1
A30: =A29+1 -> 29 | B30: Tartalomtervezés | C30: A szövegblokkok, listák balra (esetleg sorkizártan) vannak igazítva | D30: 1 | I30: 1 | J30: =IF(D30=1,I30,IF(H30=TRUE,-5,"")) -> 1 | K30: =IF(F30=1,I30,IF(H30=TRUE,-5,"")) | L30: =IF(J30=K30,0,1) -> 1
A31: =A30+1 -> 30 | B31: Tartalomtervezés | C31: A <video> taggel beillesztett videóállományból ki van vágva jellemző képkocka és poszterként be van állítva, hogy segítse a felhasználót annak eldöntésében, hogy érdemes-e megtekintenie a filmet. | D31: 1 | I31: 3 | J31: =IF(D31=1,I31,IF(H31=TRUE,-5,"")) -> 3 | K31: =IF(F31=1,I31,IF(H31=TRUE,-5,"")) | L31: =IF(J31=K31,0,1) -> 1
A32: =A31+1 -> 31 | B32: Tartalomtervezés | C32: Ugyanazok a szerkezeti linkek szerepelnek minden oldalon, ugyanolyan sorrendben | D32: 1 | I32: 1 | J32: =IF(D32=1,I32,IF(H32=TRUE,-5,"")) -> 1 | K32: =IF(F32=1,I32,IF(H32=TRUE,-5,"")) | L32: =IF(J32=K32,0,1) -> 1
... A34: =A33+1 -> 33 | B34: Tartalomtervezés | C34: Ha valaki külső oldalról érkezik a weblap egy oldalára, egyértelműen kiderül számára, hogy melyik oldalon van (pl. aktuális oldal megkülönböztetése a menüben, nyomvonal navigáció stb.) Nem elegendő a menüpont nevét (például) címsorként megismételni. | D34: 1 | I34: 2 | J34: =IF(D34=1,I34,IF(H34=TRUE,-5,"")) -> 2 | K34: =IF(F34=1,I34,IF(H34=TRUE,-5,"")) | L34: =IF(J34=K34,0,1) -> 1
A35: =A34+1 -> 34 | B35: Akadálymentesség | C35: A nem design célú képeknél az ALT attribútum precízen ki van töltve (mindegyik képnél) (WCAG 2.0 1.1.1-es feltétel) | D35: 1 | H35: TRUE | I35: 4 | J35: =IF(D35=1,I35,IF(H35=TRUE,-5,"")) -> 4 | K35: =IF(F35=1,I35,IF(H35=TRUE,-5,"")) -> -5 | L35: =IF(J35=K35,0,1) -> 1
A36: =A35+1 -> 35 | B36: Akadálymentesség | C36: A linkek szövegei önmagukban jól érthetőek (a "kattints ide" szöveg nem megfelelő), tömörek | D36: 1 | I36: 1 | J36: =IF(D36=1,I36,IF(H36=TRUE,-5,"")) -> 1 | K36: =IF(F36=1,I36,IF(H36=TRUE,-5,"")) | L36: =IF(J36=K36,0,1) -> 1
A37: =A36+1 -> 36 | B37: Akadálymentesség | C37: A szövegek jól olvashatóak, megfelelő kontrasztarány biztosított. (WCAG 2.0 1.4.3-as feltétel) | D37: 1 | H37: TRUE | I37: 2 | J37: =IF(D37=1,I37,IF(H37=TRUE,-5,"")) -> 2 | K37: =IF(F37=1,I37,IF(H37=TRUE,-5,"")) -> -5 | L37: =IF(J37=K37,0,1) -> 1
A38: =A37+1 -> 37 | B38: Akadálymentesség | C38: Alternatív, nagybetűs, nagy kontrasztú stílus változat érhető el a gyengénlátó felhasználók számára minden oldalon. | D38: 1 | E38: a fejlécben lehet kiválasztani a light mode és dark mode mellett. | I38: 5 | J38: =IF(D38=1,I38,IF(H38=TRUE,-5,"")) -> 5 | K38: =IF(F38=1,I38,IF(H38=TRUE,-5,"")) | L38: =IF(J38=K38,0,1) -> 1
A39: =A38+1 -> 38 | B39: Akadálymentesség | C39: Blokkok elkerülése: Minden oldalon hozzáférhető egy mechanizmus, melynek segítségével elkerülhetők azok a tartalmi blokkok, amelyek több oldalon is ismétlődnek (pl. képernyőről kipozícionált hivatkozás használatával) (WCAG 2.0 2.4.1-es feltétel) A tartalomra ugrás céljára használt linket a képernyőolvasó programot használók számára kell elérhetővé tennünk, a vizuális böngészőprogramokban ne jelenjenek meg, kivéve amikor fókuszba kerülnek. | D39: 1 | H39: TRUE | I39: 3 | J39: =IF(D39=1,I39,IF(H39=TRUE,-5,"")) -> 3 | K39: =IF(F39=1,I39,IF(H39=TRUE,-5,"")) -> -5 | L39: =IF(J39=K39,0,1) -> 1
A40: =A39+1 -> 39 | B40: Akadálymentesség | C40: A videónál szerepel annak teljes szövegű leírása. A leírásnak minden lényeges történést tartalmaznia kell, ami a videóban látható vagy hallható, nem elegendő néhány szóban csak összefoglalni a videó tartalmát. Célszerű külön HTML-állományban elhelyezni, és a videó után belinkelni, vagy <details><summary> tagekben elhelyezni a videó után. A pont csak akkor adható meg, ha a videó legalább 30 másodperc hosszú, legalább 15 másodpercig beszélnek a résztvevők vagy a narrátor, nem csak statikus a háttere, vagyis vannak benne vizuális történések) | D40: 1 | E40: A index.html legutolsó videója alatt van a lenyitható "Videó részletes szöveges leírása" | I40: 5 | J40: =IF(D40=1,I40,IF(H40=TRUE,-5,"")) -> 5 | K40: =IF(F40=1,I40,IF(H40=TRUE,-5,"")) | L40: =IF(J40=K40,0,1) -> 1
A41: =A40+1 -> 40 | B41: Akadálymentesség | C41: Az oldal nyelve mindegyik oldalon beállításra került. Ahol az alapértelmezett nyelvtől eltérő szöveg is van az oldalon, az el van látva a megfelelő nyelvkóddal. | D41: 1 | I41: 2 | J41: =IF(D41=1,I41,IF(H41=TRUE,-5,"")) -> 2 | K41: =IF(F41=1,I41,IF(H41=TRUE,-5,"")) | L41: =IF(J41=K41,0,1) -> 1
...

Sheet Ponthatárok
B1: Honlap irányelvek
C2: =Fedőlap!D11 -> 100
B3: 0.49 | C3: -100 | D3: elégtelen | H3: 56 | I3: 29 | J3: =(H3-I3)*16/56 -> 7.7142857
B4: 0.62 | C4: =ROUNDDOWN($C$2*B3+1,0) -> 50 | D4: elégséges | H4: =H3/2 -> 28
B5: 0.75 | C5: =ROUNDDOWN($C$2*B4+1,0) -> 63 | D5: közepes
B6: 0.88 | C6: =ROUNDDOWN($C$2*B5+1,0) -> 76 | D6: jó
B7: 1 | C7: =ROUNDDOWN($C$2*B6+1,0) -> 89 | D7: jeles
D9: TRUE
D10: FALSE
